Workbook
Name compliance_and_ethical_principles: Listas!$B$2:$B$7
Name dc_online_async: Listas!$I$2:$I$5
Name dc_online_sync: Listas!$J$2:$J$3
Name dc_presence: Listas!$K$2:$K$3
Name delivery_channels: Listas!$H$2:$H$4
Name digital_y_data_management: Listas!$C$2:$C$5
Name hseq: Listas!$D$2:$D$5
Name human_skills: Listas!$E$2:$E$6
Name languaje: Listas!$F$2:$F$6
Name mandatorio: Listas!$L$2:$L$6
Name parents: Listas!$A$2:$A$7
Name technical_and_functional_competencies: Listas!$G$2:$G$7

Sheet Usuarios
A1: Mail | B1: ID | C1: Nombres | D1: Apellidos | E1: Fecha incio (MM/DD/AA) | F1: Fecha término (MM/DD/AA) | G1: Nombre Formación | H1: Breve descripción de la formación | I1: Horas totales de formación | J1: Minutos totales de formación | K1: Parent Subjet | L1: Main Subjet | M1: Delivery Channel | N1: Tipo de entrega | O1: Mandatorio
B2: =VLOOKUP(A2,Mail!$A$1:$D$62354,2,FALSE) -> #N/A | C2: =VLOOKUP(A2,Mail!$A$1:$D$62354,3,FALSE) -> #N/A | D2: =VLOOKUP(A2,Mail!$A$1:$D$62354,4,FALSE) -> #N/A
B3: =VLOOKUP(A3,Mail!$A$1:$D$62354,2,FALSE) -> #N/A | C3: =VLOOKUP(A3,Mail!$A$1:$D$62354,3,FALSE) -> #N/A | D3: =VLOOKUP(A3,Mail!$A$1:$D$62354,4,FALSE) -> #N/A
B4: =VLOOKUP(A4,Mail!$A$1:$D$62354,2,FALSE) -> #N/A | C4: =VLOOKUP(A4,Mail!$A$1:$D$62354,3,FALSE) -> #N/A | D4: =VLOOKUP(A4,Mail!$A$1:$D$62354,4,FALSE) -> #N/A
B5: =VLOOKUP(A5,Mail!$A$1:$D$62354,2,FALSE) -> #N/A | C5: =VLOOKUP(A5,Mail!$A$1:$D$62354,3,FALSE) -> #N/A | D5: =VLOOKUP(A5,Mail!$A$1:$D$62354,4,FALSE) -> #N/A
B6: =VLOOKUP(A6,Mail!$A$1:$D$62354,2,FALSE) -> #N/A | C6: =VLOOKUP(A6,Mail!$A$1:$D$62354,3,FALSE) -> #N/A | D6: =VLOOKUP(A6,Mail!$A$1:$D$62354,4,FALSE) -> #N/A
B7: =VLOOKUP(A7,Mail!$A$1:$D$62354,2,FALSE) -> #N/A | C7: =VLOOKUP(A7,Mail!$A$1:$D$62354,3,FALSE) -> #N/A | D7: =VLOOKUP(A7,Mail!$A$1:$D$62354,4,FALSE) -> #N/A
B8: =VLOOKUP(A8,Mail!$A$1:$D$62354,2,FALSE) -> #N/A | C8: =VLOOKUP(A8,Mail!$A$1:$D$62354,3,FALSE) -> #N/A | D8: =VLOOKUP(A8,Mail!$A$1:$D$62354,4,FALSE) -> #N/A
B9: =VLOOKUP(A9,Mail!$A$1:$D$62354,2,FALSE) -> #N/A | C9: =VLOOKUP(A9,Mail!$A$1:$D$62354,3,FALSE) -> #N/A | D9: =VLOOKUP(A9,Mail!$A$1:$D$62354,4,FALSE) -> #N/A
B10: =VLOOKUP(A10,Mail!$A$1:$D$62354,2,FALSE) -> #N/A | C10: =VLOOKUP(A10,Mail!$A$1:$D$62354,3,FALSE) -> #N/A | D10: =VLOOKUP(A10,Mail!$A$1:$D$62354,4,FALSE) -> #N/A
B11: =VLOOKUP(A11,Mail!$A$1:$D$62354,2,FALSE) -> #N/A | C11: =VLOOKUP(A11,Mail!$A$1:$D$62354,3,FALSE) -> #N/A | D11: =VLOOKUP(A11,Mail!$A$1:$D$62354,4,FALSE) -> #N/A
B12: =VLOOKUP(A12,Mail!$A$1:$D$62354,2,FALSE) -> #N/A | C12: =VLOOKUP(A12,Mail!$A$1:$D$62354,3,FALSE) -> #N/A | D12: =VLOOKUP(A12,Mail!$A$1:$D$62354,4,FALSE) -> #N/A
B13: =VLOOKUP(A13,Mail!$A$1:$D$62354,2,FALSE) -> #N/A | C13: =VLOOKUP(A13,Mail!$A$1:$D$62354,3,FALSE) -> #N/A | D13: =VLOOKUP(A13,Mail!$A$1:$D$62354,4,FALSE) -> #N/A
... B41: =VLOOKUP(A41,Mail!$A$1:$D$62354,2,FALSE) -> #N/A | C41: =VLOOKUP(A41,Mail!$A$1:$D$62354,3,FALSE) -> #N/A | D41: =VLOOKUP(A41,Mail!$A$1:$D$62354,4,FALSE) -> #N/A

Sheet Mail
A1: Mail | B1: Global ID | C1: Nombre | D1: Apellido
A2: JENNIFER.MCLAIN@ENEL.COM | B2: 14502484 | C2: Jennifer Gaylene | D2: McLain
A3: ANDREA.ALLEVA@ENEL.COM | B3: 22045500 | C3: Andrea | D3: Alleva
A4: SEAN.GIBBONS@ENEL.COM | B4: 10005134 | C4: Sean | D4: Gibbons
A5: RUSTY.NELSON@ENEL.COM | B5: 14500007 | C5: Rusty L | D5: Nelson
A6: STEPHEN.CHANDLER@ENEL.COM | B6: 14500034 | C6: Stephen | D6: Chandler
A7: DANIEL.ASPELL@ENEL.COM | B7: 14500052 | C7: Daniel | D7: Aspell
A8: CHRIS.JENSEN@ENEL.COM | B8: 14500307 | C8: Christopher | D8: Jensen
A9: NATHAN.HRIBAR@ENEL.COM | B9: 14500412 | C9: Nathan Todd | D9: Hribar
A10: CHANNON.PRICE@ENEL.COM | B10: 14500603 | C10: Channon H | D10: Price
A11: GREGORY.THOLE@ENEL.COM | B11: 14500842 | C11: Gregory S | D11: Thole
A12: GARY.TAJCHMAN@ENEL.COM | B12: 14502308 | C12: Gary Neil | D12: Tajchman
A13: JOSHUA.KNIGHT@ENEL.COM | B13: 14505515 | C13: Joshua BRUCE | D13: Knight
... A5309: MIGUELANGEL.ASUN@ENEL.COM | B5309: 37342 | C5309: MIGUEL ANGEL | D5309: ASUN PEREZ
B5310: 37349 | C5310: NAME NK 1098 | D5310: SUNMNAME NK 1098
A5311: ANDRES.MARTIN@ENEL.COM | B5311: 37352 | C5311: ANDRES | D5311: MARTIN SANCHEZ DE MORA
A5312: ENRIQUE.QUIROS@ENEL.COM | B5312: 37358 | C5312: ENRIQUE | D5312: QUIROS GONZALEZ
A5313: JOSE.NADALBOLEA@ENEL.COM | B5313: 37361 | C5313: JOSE MARIA | D5313: NADAL BOLEA
A5314: CARLOS.GALITO@ENEL.COM | B5314: 37364 | C5314: CARLOS | D5314: GALITO PAU
A5315: SERGIO.CAPUJARGUIS@ENEL.COM | B5315: 37365 | C5315: SERGIO | D5315: CAPUJ ARGUIS
A5316: MANUEL.MATEO@ENEL.COM | B5316: 37372 | C5316: MANUEL | D5316: MATEO RODRIGUEZ
A5317: TOMAS.ALVAREZ@ENEL.COM | B5317: 37373 | C5317: TOMAS | D5317: ALVAREZ TEJEDOR
A5318: JOSEANTONIO.LIANO@ENEL.COM | B5318: 37376 | C5318: JOSE ANTONIO | D5318: LIAÑO LIAÑO
A5319: ERNESTO.SALA@ENEL.COM | B5319: 37380 | C5319: ERNESTO | D5319: SALA CALLEJA
A5320: JOSEANTONIO.GALLEGO@ENEL.COM | B5320: 37382 | C5320: JOSE ANTONIO | D5320: GALLEGO MARTIN
A5321: ALBERTO.GARCIAG@ENEL.COM | B5321: 37383 | C5321: ALBERTO | D5321: GARCIA GARCIA-RINCON
A5322: RAFAELALBERTO.OLIVA@ENEL.COM | B5322: 37390 | C5322: RAFAEL ALBERTO | D5322: OLIVA ORBELLO
... A6612: DAVID.MARTINL@ENEL.COM | B6612: 57523 | C6612: DAVID | D6612: MARTIN LEMES
B6613: 57529 | C6613: NAME NK 1149 | D6613: SUNMNAME NK 1149 BOBED
A6614: JUAN.GONZALEZG@ENEL.COM | B6614: 57530 | C6614: JUAN | D6614: GONZALEZ GARMENDIA
A6615: GADIFERM.FERNANDEZ@ENEL.COM | B6615: 57532 | C6615: GADIFER MARCIAL | D6615: FERNANDEZ DELGADO
A6616: FRANCISCO.VINAGRE@ENEL.COM | B6616: 57541 | C6616: FRANCISCO | D6616: VINAGRE TOME
A6617: JOSE.NIETOC@ENEL.COM | B6617: 57556 | C6617: JOSE | D6617: NIETO CESPON
A6618: GUSTAVO.SANCHEZ@ENEL.COM | B6618: 57559 | C6618: GUSTAVO JOSE | D6618: SANCHEZ CALDERIN
A6619: MARIO.APARICIO@ENEL.COM | B6619: 57564 | C6619: MARIO | D6619: APARICIO SAEZ-BRAVO
A6620: JOSECARLOS.ALMEIDA@ENEL.COM | B6620: 57565 | C6620: JOSE CARLOS | D6620: ALMEIDA GARCIA
A6621: FRANCISCOANTONIO.ARJONA@ENEL.COM | B6621: 57566 | C6621: FRANCISCO ANTONIO | D6621: ARJONA RODRIGUEZ
A6622: KEILA.BELANDO@ENEL.COM | B6622: 57568 | C6622: KEILA | D6622: BELANDO BACA
A6623: FERRAN.PRUNONOSA@ENEL.COM | B6623: 57570 | C6623: FERRAN | D6623: PRUÑONOSA CERDAN
A6624: VICTOR.MORO@ENEL.COM | B6624: 57571 | C6624: VICTOR | D6624: MORO BESA
...

Sheet Hoja2
A1: Parent subject | B1: Main Subject | D1: Delivery Channel | E1: Tipo de entrega
A2: Compliance and Ethical principles | B2: Anticorruption, antitrust | D2: Online Async | E2: Material
B3: Code of Ethics | E3: Online Courses
B4: Compliance, gdpr & privacy | E4: Test
B5: Cybersecurity | E5: Video
B6: Human Rights | D6: Online Sync | E6: Virtual Classroom
B7: Security | E7: Webinar
A8: Digital y Data Management | B8: A.I. and new technologies | D8: Presence | E8: Classroom
B9: Dara analytics, management and visualization | E9: Offsite
B10: Digital mindset & behavior
B11: Software and tools | D11: Mandatory Infotype
A12: HSEQ | B12: Environment | D12: Mandatory by law for holding
B13: Health and wellbeing | D13: Mandatory by law for HSEQ
B14: Quality | D14: Mandatory by security
D15: Mandatory by business
B16: Safety | D16: No mandatory
A18: Human Skills | B18: Cognitive skills | D18: Categoría CSR (Categoría de Sostenibilidad) | E18: Se debe eliminar : Digital y Safety
B19: Cross soft skills
B20: Diversity & inclusion
B21: Execution skills
B22: Relation Skills
A23: Languaje | B23: English
B24: Italian
B25: Other
B26: Portuguese
B27: Spanish
A28: Technical and functional competencies | B28: Cross funciion
B29: EGP&TGX
B30: Global market
B31: Grids
B32: Services
B33: Staff function

Sheet Desplegables
B1: Eliminado | C1: Perfil
B2: Sí | C2: ADMINISTRADOR
B3: No | C3: USUARIO

Sheet Listas
A1: Parents | B1: compliance_and_ethical_principles | C1: digital_y_data_management | D1: hseq | E1: human_skills | F1: languaje | G1: technical_and_functional_competencies | H1: delivery_channels | I1: dc_online_async | J1: dc_online_sync | K1: dc_presence | L1: mandatorio
A2: Compliance and Ethical principles | B2: Anticorruption, antitrust | C2: A.I. and new technologies | D2: Environment | E2: Cognitive skills | F2: English | G2: Cross funciion | H2: Online Async | I2: Material | J2: Virtual Classroom | K2: Classroom | L2: Mandatory by law for holding
A3: Digital y Data Management | B3: Code of Ethics | C3: Dara analytics, management and visualization | D3: Health and wellbeing | E3: Cross soft skills | F3: Italian | G3: EGP&TGX | H3: Online Sync | I3: Online Courses | J3: Webinar | K3: Offsite | L3: Mandatory by law for HSEQ
A4: HSEQ | B4: Compliance, gdpr & privacy | C4: Digital mindset & behavior | D4: Quality | E4: Diversity & inclusion | F4: Other | G4: Global market | H4: Presence | I4: Test | L4: Mandatory by security
A5: Human Skills | B5: Cybersecurity | C5: Software and tools | D5: Safety | E5: Execution skills | F5: Portuguese | G5: Grids | I5: Video | L5: Mandatory by business
A6: Languaje | B6: Human Rights | E6: Relation Skills | F6: Spanish | G6: Services | L6: No mandatory
A7: Technical and functional competencies | B7: Security | G7: Staff function
